I'm sorry, but an uncaught exception occurred.

While running game code:
  File "game/script.rpy", line 97, in script
    if fail == False:
  File "game/script.rpy", line 97, in <module>
    if fail == False:
NameError: name 'fail' is not defined

-- Full Traceback ------------------------------------------------------------

Full traceback:
  File "game/script.rpy", line 97, in script
    if fail == False:
  File "/home/jrcarguy11/renpy-8.3.7-sdk/renpy/ast.py", line 1856, in execute
    if renpy.python.py_eval(condition):
  File "/home/jrcarguy11/renpy-8.3.7-sdk/renpy/python.py", line 1218, in py_eval
    return py_eval_bytecode(code, globals, locals)
  File "/home/jrcarguy11/renpy-8.3.7-sdk/renpy/python.py", line 1211, in py_eval_bytecode
    return eval(bytecode, globals, locals)
  File "game/script.rpy", line 97, in <module>
    if fail == False:
NameError: name 'fail' is not defined

Linux-6.6.66-06602-g2b73872e56ce-x86_64-with-glibc2.36 x86_64
Ren'Py 8.3.7.25031702
Echo Chaser 1.0
Fri Apr  4 13:57:34 2025
